<?xml version="1.0"?>
<robot name="wheel" xmlns:xacro="http://www.ros.org/wiki/xacro">

    <xacro:property name="PI" value="3.1415926535897931" />

    <!-- Wheels -->
    <xacro:property name="wheel_radius" value="${0.203/2}" />
    <xacro:property name="wheel_height" value="0.078"      />
    <xacro:property name="wheel_mass"   value="1.6"        /> <!-- in kg-->

    <xacro:macro name="cylinder_inertia" params="m r h">
        <inertia  ixx="${m*(3*r*r + h*h)/12}" ixy = "0" ixz = "0"
                  iyy="${m*r*r/2}"          iyz = "0"
                  izz="${m*(3*r*r + h*h)/12}"
        />
    </xacro:macro>

    <xacro:macro name="omni_wheel" params="prefix parent *origin reflect">

        <joint name="${prefix}_wheel_joint" type="continuous">
            <parent link="${parent}"/>
            <child  link="${prefix}_wheel_link"/>
            <xacro:insert_block name="origin" />
            <axis xyz="0 1 0" rpy="0 0 0" />
            <limit effort="100" velocity="100"/>
            <dynamics damping="3.0" friction="5.0"/>
        </joint>

        <link name="${prefix}_wheel_link">
            <visual>
                <origin xyz="0 0 0" rpy="0 0 0" />
                <xacro:if value="${reflect}">
                    <geometry>
                        <mesh filename="package://cerlab_mecanum/meshes/omni_wheel_1.dae" scale="0.8 0.8 0.8"/>
                    </geometry>
                </xacro:if>
                <xacro:unless value="${reflect}">
                    <geometry>
                        <mesh filename="package://cerlab_mecanum/meshes/omni_wheel_2.dae" scale="0.8 0.8 0.8"/>
                    </geometry>
                </xacro:unless>
            </visual>

            <collision>
                    <origin xyz="0 0 0" rpy="${PI/2} 0 0" />
                <geometry>
                    <cylinder length="${wheel_height}" radius="${wheel_radius}" />
                </geometry>
            </collision>

            <inertial>
                <mass value="${wheel_mass}" />
                <origin xyz="0 0 0" />
                <cylinder_inertia  m="${wheel_mass}" r="${wheel_radius}" h="${wheel_height}" />
            </inertial>
        </link>

        <!-- Transmission is important to link the joints and the controller (see summit_xl_control/config/summit_xl_control.yaml)-->
        <transmission name="${prefix}_wheel_joint_trans">
            <type>transmission_interface/SimpleTransmission</type>
            <joint name="${prefix}_wheel_joint" >
                <hardwareInterface>hardware_interface/VelocityJointInterface</hardwareInterface>
            </joint>
        </transmission>

        <gazebo reference="${prefix}_wheel_link">
            <gravity>true</gravity>
            <selfCollide>false</selfCollide>
            <mu1>30</mu1>
            <mu2>30</mu2>
            <kp>1e50</kp>
            <kd>1e50</kd>
        </gazebo>

    </xacro:macro>
</robot>
